<sdf version='1.7'>
  <world name='default'>
    <light name='sun' type='directional'>
      <cast_shadows>1</cast_shadows>
      <pose>0 0 10 0 -0 0</pose>
      <diffuse>0.8 0.8 0.8 1</diffuse>
      <specular>0.2 0.2 0.2 1</specular>
      <attenuation>
        <range>1000</range>
        <constant>0.9</constant>
        <linear>0.01</linear>
        <quadratic>0.001</quadratic>
      </attenuation>
      <direction>0.5 0.1 -0.9</direction>
      <spot>
        <inner_angle>0</inner_angle>
        <outer_angle>0</outer_angle>
        <falloff>0</falloff>
      </spot>
    </light>
    <scene>
      <ambient>0.4 0.4 0.4 1</ambient>
      <background>0.7 0.7 0.7 1</background>
      <shadows>1</shadows>
    </scene>
    <physics type='ode'>
      <max_step_size>0.01</max_step_size>
      <real_time_factor>1</real_time_factor>
      <real_time_update_rate>100</real_time_update_rate>
    </physics>
    <model name='ground_plane_0'>
      <static>1</static>
      <link name='link'>
        <collision name='collision'>
          <geometry>
            <plane>
              <normal>0 0 1</normal>
              <size>100 100</size>
            </plane>
          </geometry>
          <surface>
            <friction>
              <ode>
                <mu>100</mu>
                <mu2>50</mu2>
              </ode>
              <torsional>
                <ode/>
              </torsional>
            </friction>
            <bounce/>
            <contact>
              <ode/>
            </contact>
          </surface>
          <max_contacts>10</max_contacts>
        </collision>
        <visual name='visual'>
          <cast_shadows>0</cast_shadows>
          <geometry>
            <plane>
              <normal>0 0 1</normal>
              <size>100 100</size>
            </plane>
          </geometry>
          <material>
            <script>
              <uri>file://media/materials/scripts/gazebo.material</uri>
              <name>Gazebo/Grey</name>
            </script>
          </material>
        </visual>
        <velocity_decay>
          <linear>0</linear>
          <angular>0</angular>
        </velocity_decay>
        <self_collide>0</self_collide>
        <kinematic>0</kinematic>
        <gravity>1</gravity>
        <enable_wind>0</enable_wind>
      </link>
      <pose>0.497681 0 0 0 -0 0</pose>
    </model>
    <state world_name='default'>
      <sim_time>409 940000000</sim_time>
      <real_time>423 897392906</real_time>
      <wall_time>1620411768 646513955</wall_time>
      <iterations>40994</iterations>
      <model name='ground_plane_0'>
        <pose>0.497681 0 0 0 -0 0</pose>
        <scale>1 1 1</scale>
        <link name='link'>
          <pose>0.497681 0 0 0 -0 0</pose>
          <velocity>0 0 0 0 -0 0</velocity>
          <acceleration>0 0 0 0 -0 0</acceleration>
          <wrench>0 0 0 0 -0 0</wrench>
        </link>
      </model>
      <model name='rosbot'>
        <pose>0.020175 -0.024016 0.040913 -9.6e-05 0.000728 0.137168</pose>
        <scale>1 1 1</scale>
        <link name='dummy'>
          <pose>0.020175 -0.024016 0.040913 -9.6e-05 0.000728 0.137168</pose>
          <velocity>-0.000395 0.000142 0.011156 -0.002336 -0.008431 0.000984</velocity>
          <acceleration>0.007598 0.055788 10.046 0.236226 0.501653 -0.142083</acceleration>
          <wrench>0.038067 0.279499 50.3305 0 -0 0</wrench>
        </link>
        <link name='front_left_wheel'>
          <pose>0.054665 0.091788 0.040917 -0.000342 -0.009523 0.137173</pose>
          <velocity>-0.000433 8.5e-05 0.011443 -0.00235 -0.010595 0.001132</velocity>
          <acceleration>-0.003963 0.07305 10.2122 0.15151 0.021617 0.060069</acceleration>
          <wrench>-0.001981 0.036525 5.10612 0 -0 0</wrench>
        </link>
        <link name='front_right_wheel'>
          <pose>0.084745 -0.126153 0.040877 -0.000174 0.121625 0.137164</pose>
          <velocity>-0.000301 0.000179 0.011479 -0.004525 -0.007595 0.000463</velocity>
          <acceleration>-0.004117 0.059271 9.98343 0.464409 0.39488 0.039131</acceleration>
          <wrench>-0.002059 0.029635 4.99172 0 -0 0</wrench>
        </link>
        <link name='rear_left_wheel'>
          <pose>-0.049345 0.077421 0.04093 -0.000243 -0.002508 0.137164</pose>
          <velocity>-0.000388 9.1e-05 0.010204 -0.002521 -0.009414 0.001363</velocity>
          <acceleration>0.010265 0.053514 10.0314 0.343537 0.168562 0.054792</acceleration>
          <wrench>0.005132 0.026757 5.01568 0 -0 0</wrench>
        </link>
        <link name='rear_right_wheel'>
          <pose>-0.019273 -0.1405 0.040919 -0.000334 0.007795 0.137196</pose>
          <velocity>-0.000402 7.6e-05 0.011368 -0.001758 -0.010119 0.000705</velocity>
          <acceleration>-0.027185 0.087784 9.91256 0.047378 0.046671 0.099144</acceleration>
          <wrench>-0.013592 0.043892 4.95628 0 -0 0</wrench>
        </link>
      </model>
      <light name='sun'>
        <pose>0 0 10 0 -0 0</pose>
      </light>
    </state>
    <gui fullscreen='0'>
      <camera name='user_camera'>
        <pose>0.2189 1.87881 18.0004 -0 1.5698 3.04015</pose>
        <view_controller>orbit</view_controller>
        <projection_type>perspective</projection_type>
      </camera>
    </gui>
    <gravity>0 0 -9.8</gravity>
    <magnetic_field>6e-06 2.3e-05 -4.2e-05</magnetic_field>
    <atmosphere type='adiabatic'/>
    <wind/>
    <spherical_coordinates>
      <surface_model>EARTH_WGS84</surface_model>
      <latitude_deg>0</latitude_deg>
      <longitude_deg>0</longitude_deg>
      <elevation>0</elevation>
      <heading_deg>0</heading_deg>
    </spherical_coordinates>
    <model name='rosbot'>
      <link name='dummy'>
        <inertial>
          <pose>-0 0 0.04003 0 -0 0</pose>
          <mass>5.01002</mass>
          <inertia>
            <ixx>0.0100024</ixx>
            <ixy>0.01</ixy>
            <ixz>3.8397e-08</ixz>
            <iyy>0.0100025</iyy>
            <iyz>0.01</iyz>
            <izz>0.01</izz>
          </inertia>
        </inertial>
        <collision name='dummy_fixed_joint_lump__collision_collision'>
          <pose>0 0 0.02 0 -0 0</pose>
          <geometry>
            <box>
              <size>0.2 0.15 0.04</size>
            </box>
          </geometry>
          <max_contacts>10</max_contacts>
          <surface>
            <contact>
              <ode/>
            </contact>
            <bounce/>
            <friction>
              <torsional>
                <ode/>
              </torsional>
              <ode/>
            </friction>
          </surface>
        </collision>
        <collision name='dummy_fixed_joint_lump__camera_link_collision_1'>
          <pose>-0.01 0 0.18 0 -0 0</pose>
          <geometry>
            <box>
              <size>0.001 0.001 0.001</size>
            </box>
          </geometry>
          <surface>
            <contact>
              <ode/>
            </contact>
            <friction>
              <ode/>
              <torsional>
                <ode/>
              </torsional>
            </friction>
            <bounce/>
          </surface>
          <max_contacts>10</max_contacts>
        </collision>
        <collision name='dummy_fixed_joint_lump__laser_collision_2'>
          <pose>0.02 0 0.058 1.5707 0 1.56682</pose>
          <geometry>
            <mesh>
              <scale>0.001 0.001 0.001</scale>
              <uri>/home/mateusz/ros_workspace/src/rosbot_description/src/rosbot_description/meshes/rplidar.dae</uri>
            </mesh>
          </geometry>
          <surface>
            <contact>
              <ode/>
            </contact>
            <friction>
              <ode/>
              <torsional>
                <ode/>
              </torsional>
            </friction>
            <bounce/>
          </surface>
          <max_contacts>10</max_contacts>
        </collision>
        <visual name='dummy_fixed_joint_lump__base_link_visual_visual'>
          <pose>0 0 -0.02 1.5707 0 1.5707</pose>
          <geometry>
            <mesh>
              <scale>0.001 0.001 0.001</scale>
              <uri>/home/mateusz/ros_workspace/src/rosbot_description/src/rosbot_description/meshes/box.dae</uri>
            </mesh>
          </geometry>
          <material>
            <script>
              <name>Gazebo/White</name>
              <uri>file://media/materials/scripts/gazebo.material</uri>
            </script>
          </material>
        </visual>
        <visual name='dummy_fixed_joint_lump__camera_link_visual_1'>
          <pose>-0.04 0 0.15 1.5707 0 1.5707</pose>
          <geometry>
            <mesh>
              <scale>0.001 0.001 0.001</scale>
              <uri>/home/mateusz/ros_workspace/src/rosbot_description/src/rosbot_description/meshes/astra.dae</uri>
            </mesh>
          </geometry>
          <material>
            <script>
              <name>Gazebo/Black</name>
              <uri>file://media/materials/scripts/gazebo.material</uri>
            </script>
          </material>
        </visual>
        <visual name='dummy_fixed_joint_lump__laser_visual_2'>
          <pose>0.02 0 0.058 1.5707 0 1.56682</pose>
          <geometry>
            <mesh>
              <scale>0.001 0.001 0.001</scale>
              <uri>/home/mateusz/ros_workspace/src/rosbot_description/src/rosbot_description/meshes/rplidar.dae</uri>
            </mesh>
          </geometry>
          <material>
            <script>
              <name>Gazebo/Black</name>
              <uri>file://media/materials/scripts/gazebo.material</uri>
            </script>
          </material>
        </visual>
        <visual name='dummy_fixed_joint_lump__top_visual_3'>
          <pose>0 0 0.055 1.5707 0 1.5707</pose>
          <geometry>
            <mesh>
              <scale>0.001 0.001 0.001</scale>
              <uri>/home/mateusz/ros_workspace/src/rosbot_description/src/rosbot_description/meshes/upper.dae</uri>
            </mesh>
          </geometry>
          <material>
            <script>
              <name>Gazebo/Red</name>
              <uri>file://media/materials/scripts/gazebo.material</uri>
            </script>
          </material>
        </visual>
        <velocity_decay/>
        <velocity_decay/>
        <velocity_decay/>
        <sensor name='openni_camera_camera' type='depth'>
          <always_on>1</always_on>
          <visualize>1</visualize>
          <camera>
            <horizontal_fov>1.047</horizontal_fov>
            <image>
              <width>640</width>
              <height>480</height>
              <format>R8G8B8</format>
            </image>
            <depth_camera>
              <output>depths</output>
            </depth_camera>
            <clip>
              <near>0.1</near>
              <far>100</far>
            </clip>
          </camera>
          <plugin name='kinect_controller' filename='libgazebo_ros_openni_kinect.so'>
            <alwaysOn>1</alwaysOn>
            <updateRate>10.0</updateRate>
            <cameraName>camera</cameraName>
            <frameName>camera_depth_frame</frameName>
            <imageTopicName>rgb/image_raw</imageTopicName>
            <depthImageTopicName>depth/image_raw</depthImageTopicName>
            <pointCloudTopicName>depth/points</pointCloudTopicName>
            <cameraInfoTopicName>rgb/camera_info</cameraInfoTopicName>
            <depthImageCameraInfoTopicName>depth/camera_info</depthImageCameraInfoTopicName>
            <pointCloudCutoff>0.4</pointCloudCutoff>
            <hackBaseline>0.07</hackBaseline>
            <distortionK1>0.0</distortionK1>
            <distortionK2>0.0</distortionK2>
            <distortionK3>0.0</distortionK3>
            <distortionT1>0.0</distortionT1>
            <distortionT2>0.0</distortionT2>
            <CxPrime>0.0</CxPrime>
            <Cx>0.0</Cx>
            <Cy>0.0</Cy>
            <focalLength>0.0</focalLength>
            <robotNamespace>/</robotNamespace>
          </plugin>
          <pose>-0.03 0 0.18 0 -0 0</pose>
        </sensor>
        <velocity_decay/>
        <sensor name='range_fl' type='ray'>
          <update_rate>5</update_rate>
          <ray>
            <scan>
              <horizontal>
                <samples>5</samples>
                <resolution>1</resolution>
                <min_angle>-0.05</min_angle>
                <max_angle>0.05</max_angle>
              </horizontal>
              <vertical>
                <samples>5</samples>
                <resolution>1</resolution>
                <min_angle>-0.05</min_angle>
                <max_angle>0.05</max_angle>
              </vertical>
            </scan>
            <range>
              <min>0.01</min>
              <max>0.9</max>
              <resolution>0.01</resolution>
            </range>
          </ray>
          <plugin name='gazebo_ros_range' filename='libgazebo_ros_range.so'>
            <gaussianNoise>0.005</gaussianNoise>
            <alwaysOn>1</alwaysOn>
            <updateRate>5</updateRate>
            <topicName>range/fl</topicName>
            <frameName>range_fl</frameName>
            <fov>0.1</fov>
            <radiation>ultrasound</radiation>
            <robotNamespace>/</robotNamespace>
          </plugin>
          <pose>0.1 0.05 0.01 0 -0 0.13</pose>
        </sensor>
        <velocity_decay/>
        <sensor name='range_fr' type='ray'>
          <update_rate>5</update_rate>
          <ray>
            <scan>
              <horizontal>
                <samples>5</samples>
                <resolution>1</resolution>
                <min_angle>-0.05</min_angle>
                <max_angle>0.05</max_angle>
              </horizontal>
              <vertical>
                <samples>5</samples>
                <resolution>1</resolution>
                <min_angle>-0.05</min_angle>
                <max_angle>0.05</max_angle>
              </vertical>
            </scan>
            <range>
              <min>0.01</min>
              <max>0.9</max>
              <resolution>0.01</resolution>
            </range>
          </ray>
          <plugin name='gazebo_ros_range' filename='libgazebo_ros_range.so'>
            <gaussianNoise>0.005</gaussianNoise>
            <alwaysOn>1</alwaysOn>
            <updateRate>5</updateRate>
            <topicName>range/fr</topicName>
            <frameName>range_fr</frameName>
            <fov>0.1</fov>
            <radiation>ultrasound</radiation>
            <robotNamespace>/</robotNamespace>
          </plugin>
          <pose>0.1 -0.05 0.01 0 0 -0.13</pose>
        </sensor>
        <velocity_decay/>
        <sensor name='range_rl' type='ray'>
          <update_rate>5</update_rate>
          <ray>
            <scan>
              <horizontal>
                <samples>5</samples>
                <resolution>1</resolution>
                <min_angle>-0.05</min_angle>
                <max_angle>0.05</max_angle>
              </horizontal>
              <vertical>
                <samples>5</samples>
                <resolution>1</resolution>
                <min_angle>-0.05</min_angle>
                <max_angle>0.05</max_angle>
              </vertical>
            </scan>
            <range>
              <min>0.01</min>
              <max>0.9</max>
              <resolution>0.01</resolution>
            </range>
          </ray>
          <plugin name='gazebo_ros_range' filename='libgazebo_ros_range.so'>
            <gaussianNoise>0.005</gaussianNoise>
            <alwaysOn>1</alwaysOn>
            <updateRate>5</updateRate>
            <topicName>range/rl</topicName>
            <frameName>range_rl</frameName>
            <fov>0.1</fov>
            <radiation>ultrasound</radiation>
            <robotNamespace>/</robotNamespace>
          </plugin>
          <pose>-0.1 0.05 0.01 0 -0 3.01</pose>
        </sensor>
        <velocity_decay/>
        <sensor name='range_rr' type='ray'>
          <update_rate>5</update_rate>
          <ray>
            <scan>
              <horizontal>
                <samples>5</samples>
                <resolution>1</resolution>
                <min_angle>-0.05</min_angle>
                <max_angle>0.05</max_angle>
              </horizontal>
              <vertical>
                <samples>5</samples>
                <resolution>1</resolution>
                <min_angle>-0.05</min_angle>
                <max_angle>0.05</max_angle>
              </vertical>
            </scan>
            <range>
              <min>0.01</min>
              <max>0.9</max>
              <resolution>0.01</resolution>
            </range>
          </ray>
          <plugin name='gazebo_ros_range' filename='libgazebo_ros_range.so'>
            <gaussianNoise>0.005</gaussianNoise>
            <alwaysOn>1</alwaysOn>
            <updateRate>5</updateRate>
            <topicName>range/rr</topicName>
            <frameName>range_rr</frameName>
            <fov>0.1</fov>
            <radiation>ultrasound</radiation>
            <robotNamespace>/</robotNamespace>
          </plugin>
          <pose>-0.1 -0.05 0.01 0 -0 -3.01319</pose>
        </sensor>
        <velocity_decay/>
        <velocity_decay/>
        <sensor name='head_rplidar_sensor' type='ray'>
          <visualize>0</visualize>
          <update_rate>40</update_rate>
          <ray>
            <scan>
              <horizontal>
                <samples>720</samples>
                <resolution>1</resolution>
                <min_angle>-3.14159</min_angle>
                <max_angle>3.14159</max_angle>
              </horizontal>
              <vertical>
                <samples>1</samples>
                <min_angle>0</min_angle>
                <max_angle>0</max_angle>
              </vertical>
            </scan>
            <range>
              <min>0.2</min>
              <max>12</max>
              <resolution>0.01</resolution>
            </range>
            <noise>
              <type>gaussian</type>
              <mean>0</mean>
              <stddev>0.01</stddev>
            </noise>
          </ray>
          <plugin name='gazebo_ros_head_rplidar_controller' filename='libgazebo_ros_laser.so'>
            <topicName>scan</topicName>
            <frameName>laser</frameName>
            <robotNamespace>/</robotNamespace>
          </plugin>
          <pose>0.02 0 0.058 0 -0 3.14</pose>
        </sensor>
        <velocity_decay/>
        <gravity>1</gravity>
        <velocity_decay/>
        <gravity>1</gravity>
        <sensor name='imu_sensor' type='imu'>
          <always_on>1</always_on>
          <update_rate>10</update_rate>
          <visualize>1</visualize>
          <topic>imu</topic>
          <plugin name='imu_plugin' filename='libgazebo_ros_imu_sensor.so'>
            <topicName>imu</topicName>
            <bodyName>imu_link</bodyName>
            <updateRateHZ>10.0</updateRateHZ>
            <gaussianNoise>0.0</gaussianNoise>
            <xyzOffset>0 0 0</xyzOffset>
            <rpyOffset>0 0 0</rpyOffset>
            <frameName>imu_link</frameName>
            <robotNamespace>/</robotNamespace>
          </plugin>
          <pose>0 0 0 0 -0 0</pose>
          <imu/>
        </sensor>
        <self_collide>0</self_collide>
        <enable_wind>0</enable_wind>
        <kinematic>0</kinematic>
      </link>
      <joint name='front_left_wheel_hinge' type='revolute'>
        <pose relative_to='dummy'>0.05 0.11 0 0 -0 0</pose>
        <parent>dummy</parent>
        <child>front_left_wheel</child>
        <axis>
          <xyz>0 1 0</xyz>
          <limit>
            <lower>-1e+16</lower>
            <upper>1e+16</upper>
          </limit>
          <dynamics>
            <spring_reference>0</spring_reference>
            <spring_stiffness>0</spring_stiffness>
          </dynamics>
        </axis>
      </joint>
      <link name='front_left_wheel'>
        <pose relative_to='front_left_wheel_hinge'>0 0 0 0 -0 0</pose>
        <inertial>
          <pose>0 0 0 -0 1.5707 1.5707</pose>
          <mass>0.5</mass>
          <inertia>
            <ixx>0.001</ixx>
            <ixy>0</ixy>
            <ixz>0</ixz>
            <iyy>0.001</iyy>
            <iyz>0</iyz>
            <izz>0.001</izz>
          </inertia>
        </inertial>
        <collision name='front_left_wheel_fixed_joint_lump__collision_collision'>
          <pose>0 0 0 0 -0 1.5707</pose>
          <geometry>
            <mesh>
              <scale>0.001 0.001 0.001</scale>
              <uri>/home/mateusz/ros_workspace/src/rosbot_description/src/rosbot_description/meshes/wheel-v2.stl</uri>
            </mesh>
          </geometry>
          <max_contacts>10</max_contacts>
          <surface>
            <contact>
              <ode/>
            </contact>
            <bounce/>
            <friction>
              <torsional>
                <ode/>
              </torsional>
              <ode/>
            </friction>
          </surface>
        </collision>
        <visual name='front_left_wheel_visual_visual'>
          <pose>0 0 0 0 -0 1.5707</pose>
          <geometry>
            <mesh>
              <scale>0.001 0.001 0.001</scale>
              <uri>/home/mateusz/ros_workspace/src/rosbot_description/src/rosbot_description/meshes/wheel.dae</uri>
            </mesh>
          </geometry>
          <material>
            <script>
              <name>Gazebo/Black</name>
              <uri>file://media/materials/scripts/gazebo.material</uri>
            </script>
          </material>
        </visual>
        <gravity>1</gravity>
        <velocity_decay/>
        <self_collide>0</self_collide>
        <enable_wind>0</enable_wind>
        <kinematic>0</kinematic>
      </link>
      <joint name='front_right_wheel_hinge' type='revolute'>
        <pose relative_to='dummy'>0.05 -0.11 0 0 -0 0</pose>
        <parent>dummy</parent>
        <child>front_right_wheel</child>
        <axis>
          <xyz>0 1 0</xyz>
          <limit>
            <lower>-1e+16</lower>
            <upper>1e+16</upper>
          </limit>
          <dynamics>
            <spring_reference>0</spring_reference>
            <spring_stiffness>0</spring_stiffness>
          </dynamics>
        </axis>
      </joint>
      <link name='front_right_wheel'>
        <pose relative_to='front_right_wheel_hinge'>0 0 0 0 -0 0</pose>
        <inertial>
          <pose>0 0 0 -0 1.5707 1.5707</pose>
          <mass>0.5</mass>
          <inertia>
            <ixx>0.001</ixx>
            <ixy>0</ixy>
            <ixz>0</ixz>
            <iyy>0.001</iyy>
            <iyz>0</iyz>
            <izz>0.001</izz>
          </inertia>
        </inertial>
        <collision name='front_right_wheel_fixed_joint_lump__collision_collision'>
          <pose>0 0 0 0 0 -1.5707</pose>
          <geometry>
            <mesh>
              <scale>0.001 0.001 0.001</scale>
              <uri>/home/mateusz/ros_workspace/src/rosbot_description/src/rosbot_description/meshes/wheel-v2.stl</uri>
            </mesh>
          </geometry>
          <max_contacts>10</max_contacts>
          <surface>
            <contact>
              <ode/>
            </contact>
            <bounce/>
            <friction>
              <torsional>
                <ode/>
              </torsional>
              <ode/>
            </friction>
          </surface>
        </collision>
        <visual name='front_right_wheel_visual_visual'>
          <pose>0 0 0 0 0 -1.5707</pose>
          <geometry>
            <mesh>
              <scale>0.001 0.001 0.001</scale>
              <uri>/home/mateusz/ros_workspace/src/rosbot_description/src/rosbot_description/meshes/wheel.dae</uri>
            </mesh>
          </geometry>
          <material>
            <script>
              <name>Gazebo/Black</name>
              <uri>file://media/materials/scripts/gazebo.material</uri>
            </script>
          </material>
        </visual>
        <gravity>1</gravity>
        <velocity_decay/>
        <self_collide>0</self_collide>
        <enable_wind>0</enable_wind>
        <kinematic>0</kinematic>
      </link>
      <joint name='rear_left_wheel_hinge' type='revolute'>
        <pose relative_to='dummy'>-0.055 0.11 0 0 -0 0</pose>
        <parent>dummy</parent>
        <child>rear_left_wheel</child>
        <axis>
          <xyz>0 1 0</xyz>
          <limit>
            <lower>-1e+16</lower>
            <upper>1e+16</upper>
          </limit>
          <dynamics>
            <spring_reference>0</spring_reference>
            <spring_stiffness>0</spring_stiffness>
          </dynamics>
        </axis>
      </joint>
      <link name='rear_left_wheel'>
        <pose relative_to='rear_left_wheel_hinge'>0 0 0 0 -0 0</pose>
        <inertial>
          <pose>0 0 0 -0 1.5707 1.5707</pose>
          <mass>0.5</mass>
          <inertia>
            <ixx>0.001</ixx>
            <ixy>0</ixy>
            <ixz>0</ixz>
            <iyy>0.001</iyy>
            <iyz>0</iyz>
            <izz>0.001</izz>
          </inertia>
        </inertial>
        <collision name='rear_left_wheel_fixed_joint_lump__collision_collision'>
          <pose>0 0 0 0 -0 1.5707</pose>
          <geometry>
            <mesh>
              <scale>0.001 0.001 0.001</scale>
              <uri>/home/mateusz/ros_workspace/src/rosbot_description/src/rosbot_description/meshes/wheel-v2.stl</uri>
            </mesh>
          </geometry>
          <max_contacts>10</max_contacts>
          <surface>
            <contact>
              <ode/>
            </contact>
            <bounce/>
            <friction>
              <torsional>
                <ode/>
              </torsional>
              <ode/>
            </friction>
          </surface>
        </collision>
        <visual name='rear_left_wheel_visual_visual'>
          <pose>0 0 0 0 -0 1.5707</pose>
          <geometry>
            <mesh>
              <scale>0.001 0.001 0.001</scale>
              <uri>/home/mateusz/ros_workspace/src/rosbot_description/src/rosbot_description/meshes/wheel.dae</uri>
            </mesh>
          </geometry>
          <material>
            <script>
              <name>Gazebo/Black</name>
              <uri>file://media/materials/scripts/gazebo.material</uri>
            </script>
          </material>
        </visual>
        <gravity>1</gravity>
        <velocity_decay/>
        <self_collide>0</self_collide>
        <enable_wind>0</enable_wind>
        <kinematic>0</kinematic>
      </link>
      <joint name='rear_right_wheel_hinge' type='revolute'>
        <pose relative_to='dummy'>-0.055 -0.11 0 0 -0 0</pose>
        <parent>dummy</parent>
        <child>rear_right_wheel</child>
        <axis>
          <xyz>0 1 0</xyz>
          <limit>
            <lower>-1e+16</lower>
            <upper>1e+16</upper>
          </limit>
          <dynamics>
            <spring_reference>0</spring_reference>
            <spring_stiffness>0</spring_stiffness>
          </dynamics>
        </axis>
      </joint>
      <link name='rear_right_wheel'>
        <pose relative_to='rear_right_wheel_hinge'>0 0 0 0 -0 0</pose>
        <inertial>
          <pose>0 0 0 -0 1.5707 1.5707</pose>
          <mass>0.5</mass>
          <inertia>
            <ixx>0.001</ixx>
            <ixy>0</ixy>
            <ixz>0</ixz>
            <iyy>0.001</iyy>
            <iyz>0</iyz>
            <izz>0.001</izz>
          </inertia>
        </inertial>
        <collision name='rear_right_wheel_fixed_joint_lump__collision_collision'>
          <pose>0 0 0 0 0 -1.5707</pose>
          <geometry>
            <mesh>
              <scale>0.001 0.001 0.001</scale>
              <uri>/home/mateusz/ros_workspace/src/rosbot_description/src/rosbot_description/meshes/wheel-v2.stl</uri>
            </mesh>
          </geometry>
          <max_contacts>10</max_contacts>
          <surface>
            <contact>
              <ode/>
            </contact>
            <bounce/>
            <friction>
              <torsional>
                <ode/>
              </torsional>
              <ode/>
            </friction>
          </surface>
        </collision>
        <visual name='rear_right_wheel_visual_visual'>
          <pose>0 0 0 0 0 -1.5707</pose>
          <geometry>
            <mesh>
              <scale>0.001 0.001 0.001</scale>
              <uri>/home/mateusz/ros_workspace/src/rosbot_description/src/rosbot_description/meshes/wheel.dae</uri>
            </mesh>
          </geometry>
          <material>
            <script>
              <name>Gazebo/Black</name>
              <uri>file://media/materials/scripts/gazebo.material</uri>
            </script>
          </material>
        </visual>
        <gravity>1</gravity>
        <velocity_decay/>
        <self_collide>0</self_collide>
        <enable_wind>0</enable_wind>
        <kinematic>0</kinematic>
      </link>
      <plugin name='skid_steer_drive_controller' filename='libgazebo_ros_skid_steer_drive.so'>
        <robotNamespace>/</robotNamespace>
        <updateRate>10.0</updateRate>
        <robotBaseFrame>/base_link</robotBaseFrame>
        <wheelSeparation>0.20</wheelSeparation>
        <wheelDiameter>0.08</wheelDiameter>
        <torque>5</torque>
        <leftFrontJoint>front_left_wheel_hinge</leftFrontJoint>
        <rightFrontJoint>front_right_wheel_hinge</rightFrontJoint>
        <leftRearJoint>rear_left_wheel_hinge</leftRearJoint>
        <rightRearJoint>rear_right_wheel_hinge</rightRearJoint>
        <topicName>cmd_vel</topicName>
        <commandTopic>cmd_vel</commandTopic>
        <broadcastTF>1</broadcastTF>
        <odometryTopic>odom</odometryTopic>
        <odometryFrame>/odom</odometryFrame>
        <covariance_x>0.000100</covariance_x>
        <covariance_y>0.000100</covariance_y>
        <covariance_yaw>0.010000</covariance_yaw>
      </plugin>
      <static>0</static>
      <plugin name='gazebo_ros_control' filename='libgazebo_ros_control.so'>
        <legacyModeNS>1</legacyModeNS>
        <robotNamespace>/</robotNamespace>
      </plugin>
      <pose>0 0 0 0 -0 0</pose>
    </model>
  </world>
</sdf>
